Workbook

Sheet 2026
A1: DAFTAR URUT KEPEGAWAIAN
A2: UPTD PUSKESMAS KUNJANG
A3: PER 14 Januari 2026
A6: NO | B6: NAMA | C6: NIP / NIK | D6: GOL | E6: JENIS ASN | F6: TMT GOL | G6: NAMA JABATAN | H6: TMT JABATAN | I6: E | J6: THN | K6: BLN | L6: MK JABATAN | M6: PENDIDIKAN | N6: KETERANGAN | O6: TEMPAT TANGGAL LAHIR | P6: AGAMA | Q6: KET
A7: 1 | B7: dr.Durotun Nafisa | C7: 19750423 200212 2 005 | D7: Ivc | E7: PNS | F7: 44835 | G7: Dokter Ahli Madya | H7: 24/8/2016 | I7: IV/c | J7: 22 | K7: 0 | L7: 9 Thn 5 Bln | M7: S1 | N7: Dokter Umum Th 1999 | O7: Kediri, 23-04-1975 | P7: Islam | Q7: Dr.durotun Nafisa
A8: 2 | B8: drg. Putri Emyta Sari | C8: 19810604 200902 2 004 | D8: Ivb | E8: PNS | F8: 45017 | G8: Dokter Gigi Ahli Madya | H8: 45017 | I8: - | J8: 13 | K8: 5 | L8: 2 Thn 9 Bln | M8: S1 | N8: FKG Th. 2006 | O8: Kediri, 04-06-1981 | P8: Islam | Q8: Drg. Putri Emyta Sari
A9: 3 | B9: Setya Budi, Amd., Kep | C9: 19700508 199203 1 003 | D9: IIId | E9: PNS | F9: 42278 | G9: Perawat Ahli pertama | H9: 42014 | I9: - | J9: 25 | K9: 4 | L9: 10 Thn 3 Bln | M9: D III | N9: AKPER Thn 2004 | O9: Kediri, 08-05-1970 | P9: Islam | Q9: Setya Budi, Amd., Kep
A10: 4 | B10: Luluk Listyaningsih,AMG | C10: 19691030 199203 2 008 | D10: IIId | E10: PNS | F10: 42644 | G10: Nutrisionis Penyelia | H10: 42379 | I10: - | J10: 25 | K10: 4 | L10: 9 Thn 3 Bln | M10: D III | N10: AKZI Thn 2003 | O10: Kediri, 30-10-1969 | P10: Islam | Q10: Luluk Listyaningsih,amg
A11: 5 | B11: Yuanendah, SST. | C11: 19710125 199203 2 010 | D11: IIId | E11: PNS | F11: 44470 | G11: Bidan Ahli Muda | H11: 42594 | I11: - | J11: 25 | K11: 4 | L11: 9 Thn 1 Bln | M11: D IV | N11: Bidan Pendidik Thn 2013 | O11: Kediri, 25-01-1971 | P11: Islam | Q11: Yuanendah, Sst.
A12: 6 | B12: Daril Rahmatullah, S. Farm. | C12: 19810704 200901 1 004 | D12: Iva | E12: PNS | F12: 45627 | G12: Apoteker Ahli Madya | H12: 45544 | I12: - | J12: 15 | K12: 11 | L12: 1 Thn 4 Bln | M12: S1 | N12: Apoteker Thn 2005 | O12: Nganjuk, 04-07-1981 | P12: Islam | Q12: Daril Rahmatullah, S. Farm.
A13: 7 | B13: Fitri Ariani Isnaningtyas, Amd.AK | C13: 19780908 199903 2 001 | D13: IIId | E13: PNS | F13: 45870 | G13: Pranata Labkes Pelaksana Penyelia | H13: 45545 | I13: - | J13: 21 | K13: 5 | L13: - | M13: D III | N13: Anls Kesh Thn 2009 | O13: Kediri, 08-09-1978 | P13: Islam | Q13: Fitri Ariani Isnaningtyas, Amd.ak
A14: 8 | B14: Rinda Ari Puspita, Amd. KG | C14: 19871127 201001 2 008 | D14: IIIb | E14: PNS | F14: 44652 | G14: Terapis Gigi dan Mulut Mahir | H14: 1/42022 | I14: - | J14: 10 | K14: 5 | L14: 3 Thn 9 Bln | M14: D III | N14: Kesh.Gigi Thn 2009 | O14: Jombang, 27-11-1987 | P14: Islam | Q14: Rinda Ari Puspita, Amd. Kg
A15: 9 | B15: dr. Rizky Rachmat Kurniawan | C15: 19960310 202203 1 005 | D15: IIIb | E15: PNS | F15: 44929 | G15: Dokter Pertama | H15: 44564 | I15: - | J15: 1 | K15: 0 | M15: S1 | N15: Dokter Umum Th 2019 | O15: Samarinda,10-03-1996 | P15: Islam | Q15: Dr. Rizky Rachmat Kurniawan
A16: 10 | B16: Supatemi, Amd.Keb | C16: 19720306 200604 2 014 | D16: IIIb | E16: PNS | F16: 45870 | G16: Bidan Mahir | H16: 44279 | I16: - | J16: 25 | K16: 10 | L16: 4 Thn 10 Bln | M16: D III | N16: AKBID Thn 2005 | O16: Kediri, 06-03-1972 | P16: Islam | Q16: Supatemi, Amd.keb
A17: 11 | B17: Anik Sri Purwati, Amd. Keb. | C17: 19740806 200604 2 022 | D17: IIIb | E17: PNS | F17: 45870 | G17: Bidan Mahir | H17: 44279 | I17: - | J17: 25 | K17: 10 | L17: 4 Thn 10 Bln | M17: D III | N17: AKBID Thn 2009 | O17: Kediri, 06-08-1974 | P17: Islam | Q17: Anik Sri Purwati, Amd. Keb.
A18: 12 | B18: Enny Nurhayati, Amd.. Keb. | C18: 19741101 200604 2 014 | D18: IIIb | E18: PNS | F18: 45931 | G18: Bidan Mahir | H18: 44279 | I18: - | J18: 27 | K18: 0 | L18: 4 Thn 10 Bln | M18: D III | N18: AKBID Thn 2009 | O18: Jombang, 01-11-1974 | P18: Islam | Q18: Enny Nurhayati, Amd.. Keb.
A19: 13 | B19: Sulisni, Amd. Keb. | C19: 19750315 200604 2 031 | D19: IIIb | E19: PNS | F19: 45870 | G19: Bidan Mahir | H19: 44279 | I19: - | J19: 24 | K19: 10 | L19: 4 Thn 10 Bln | M19: D III | N19: AKBID Thn 2012 | O19: Jombang, 15-03-1975 | P19: Islam | Q19: Sulisni, Amd. Keb.
A20: 14 | B20: Estu Rahayuningsih, Amd. Keb. | C20: 19751117 200701 2 010 | D20: IIIb | E20: PNS | F20: 45931 | G20: Bidan Mahir | H20: 45931 | I20: - | J20: 25 | K20: 0 | M20: D III | N20: AKBID Thn 2012 | O20: Pati, 17-11-1975 | P20: Kristen | Q20: Estu Rahayuningsih, Amd. Keb.
A21: 15 | B21: Prihatiningtyas, Amd. Keb. | C21: 19760521 200701 2 012 | D21: IIIb | E21: PNS | F21: 45931 | G21: Bidan Mahir | H21: 45931 | I21: - | J21: 25 | K21: 0 | M21: D III | N21: AKBID Thn 2012 | O21: Kediri, 21-05-1976 | P21: Islam | Q21: Prihatiningtyas, Amd. Keb.
A22: 16 | B22: Mey Idayati, Amd.Kep | C22: 19870507 201402 2 001 | D22: IIIb | E22: PNS | F22: 45200 | G22: Perawat Mahir | H22: 43922 | I22: - | J22: 10 | K22: 4 | L22: 5 Thn 9 Bln | M22: D III | N22: Keperawatan, 2010 | O22: Kediri, 07-05-1987 | P22: Islam | Q22: Mey Idayati, Amd.kep
A23: 17 | B23: Sito Luncono Setio Utomo | C23: 19790506 201001 1 027 | D23: lld | E23: PNS | F23: 44652 | G23: Pengadministrasi Kepegawaian | H23: 44385 | I23: - | J23: 17 | K23: 6 | M23: SLTA | N23: SMA Thn. | O23: Surabaya, 06-05-1979 | P23: Islam | Q23: Sito Luncono Setio Utomo
A24: 18 | B24: Siti Aminah, Amd Kep. | C24: 19870803 201903 2 005 | D24: IId | E24: PNS | F24: 44835 | G24: Perawat Terampil | H24: 44403 | I24: - | J24: 6 | K24: 9 | M24: DIII | N24: AKPER Thn 2009 | O24: Kediri,03-08-1987 | P24: Islam | Q24: Siti Aminah, Amd Kep.
A25: 19 | B25: Nuryana Vidya C, Amd.Kep | C25: 19970326 202012 2 013 | D25: IId | E25: PNS | F25: 45444 | G25: Perawat Terampil | H25: 44531 | I25: - | J25: 6 | K25: 6 | L25: 4 Thn 1 Bln | M25: D III | N25: AKPER Thn.2018 | O25: Kediri, 26-03-1997 | P25: Islam | Q25: Nuryana Vidya C, Amd.kep
A26: 20 | B26: Novia Anjarwati, Amd. Kes | C26: 19951125 202012 2 013 | D26: IId | E26: PNS | F26: 45444 | G26: Sanitarian Pelaksana | H26: 44531 | I26: - | J26: 6 | K26: 6 | L26: 4 Thn 1 Bln | M26: D III | N26: Kesling Thn. 2018 | O26: Nganjuk, 25-11-1995 | P26: Islam | Q26: Novia Anjarwati, Amd. Kes
A27: 21 | B27: Dinung Wahyu Purwanti | C27: 19930105 202221 2 001 | D27: PPPK-VII | E27: PPPK | F27: 44562 | G27: Bidan Terampil | H27: 44562 | J27: - | K27: - | L27: 4 Thn 0 Bln | M27: D III | N27: Bidan Terampil | O27: Kediri, 05- 01-1993 | P27: Islam | Q27: Dinung Wahyu Purwanti
A28: 22 | B28: Susi Winda Wandari, Amd Keb | C28: 19940405 202321 2 005 | D28: PPPK-VII | E28: PPPK | F28: 44930 | G28: Bidan Terampil | H28: 44930 | I28: - | J28: - | K28: - | L28: 2 Thn 9 Bln | M28: D-III | N28: AKBID Thn 2015 | O28: Kediri, 05-04-1994 | P28: Islam | Q28: Susi Winda Wandari, Amd Keb
A29: 23 | B29: Desi Natalia, SST | C29: 3506216412890001 | D29: PPPK-VII | E29: PPPK-PW | F29: 45962 | G29: Bidan Terampil | H29: 42370 | I29: - | J29: - | K29: - | L29: 10 Thn 0 Bln | M29: D-IV | N29: Kebidanan Thn. 2011 | O29: Kediri, 24-12-1989 | P29: Islam | Q29: Desi Natalia, Sst
A30: 24 | B30: Devi Ardianti, SE | C30: 3506164503950002 | D30: PPPK-VII | E30: PPPK-PW | F30: 45962 | G30: Penata Layanan Operasional | H30: 42758 | I30: - | J30: - | K30: - | L30: 9 Thn 0 Bln | M30: S-1 | N30: Akuntansi Thn 2016 | O30: Kediri, 05-03-1995 | P30: Islam | Q30: Devi Ardianti, Se
A31: 25 | B31: Vivi Juni Mega A, S.Tr.Keb | C31: 3506214506950001 | D31: PPPK-VII | E31: PPPK-PW | F31: 45962 | G31: Bidan Terampil | H31: 43497 | I31: - | J31: - | K31: - | L31: 6 Thn 11 Bln | M31: D-IV | N31: AKBID Thn.2013 | O31: Kediri, 05-06-1995 | P31: Islam | Q31: Vivi Juni Mega A, S.tr.keb
A32: 26 | B32: Anieta Yuni Purnawati, Amd.Keb | C32: 3506215706900001 | D32: PPPK-VII | E32: PPPK | F32: 45294 | G32: Bidan Terampil | H32: 45294 | I32: - | J32: - | K32: - | L32: 1 Thn 10 Bln | M32: D-III | N32: AKBID Thn 2017 | O32: Kediri, 17-06-1990 | P32: Islam | Q32: Anieta Yuni Purnawati, Amd.keb
A33: 27 | B33: Slamet Riadi | C33: 3506212005790003 | D33: PPPK-V | E33: PPPK-PW | F33: 45962 | G33: Operator Layanan Operasional | H33: 35643 | I33: - | J33: - | K33: - | L33: 29 Thn 0 Bln | M33: SMA | N33: Thn 2008 | O33: Kediri, 20-05-1979 | P33: Islam | Q33: Slamet Riadi
A34: 28 | B34: Anita Sumariati | C34: 3506214101850002 | D34: KONTRAK | F34: - | G34: KEBERSIHAN | H34: 43101 | I34: - | J34: - | K34: - | L34: 8 Thn 0 Bln | M34: SMP | N34: Thn 2000 | O34: Madiun, 02-01-1985 | P34: Islam | Q34: Anita Sumariati
A35: 29 | B35: Mimin Asmawati | C35: 3506215707790002 | D35: KONTRAK | F35: - | G35: KEBERSIHAN | H35: 01/01/2020 | I35: - | J35: - | K35: - | L35: 6 Thn 0 Bln | M35: SMK | N35: Thn 1999 | O35: Kediri, 17-07-1979 | P35: Islam | Q35: Mimin Asmawati
A36: 30 | B36: Fitria Indriyani | C36: 3506215502970001 | D36: PPPK-V | E36: PPPK-PW | F36: 45962 | G36: Operator Layanan Operasional | H36: 43222 | I36: - | J36: - | K36: - | L36: 7 Thn 11 Bln | M36: D-1 | N36: Manajemen Farmasi Thn 2017 | O36: Kediri, 15-02-1997 | P36: Islam | Q36: Fitria Indriyani
A37: 31 | B37: Cendy Santia KS, Amd AK | C37: 3506154409920001 | D37: PPPK-VII | E37: PPPK-PW | F37: 45962 | G37: Pranata Labkes Terampil | H37: 43832 | I37: - | J37: - | K37: - | L37: 5 Thn 11 Bln | M37: D-III | N37: Analis Kesh Thn 2016 | O37: Analis Kesh Thn 2016 | P37: Islam | Q37: Cendy Santia Ks, Amd Ak
A38: 32 | B38: Mistiani Saputri, Amd Kom | C38: 3506266204980003 | D38: PPPK-VII | E38: PPPK-PW | F38: 45962 | G38: Pengelola Layanan Operasional | H38: 44256 | I38: - | J38: - | K38: - | L38: 4 Thn 10 Bln | M38: D-III | N38: Manajemen Informatika Thn. 2019 | O38: Kediri, 22-04-1998 | P38: Islam | Q38: Mistiani Saputri, Amd Kom
A39: 33 | B39: Rani Rosita , Amd Keb | C39: 3506265409920003 | D39: PPPK-VII | E39: PPPK-PW | F39: 45962 | G39: Bidan Terampil | H39: 31/04/2020 | I39: - | J39: - | K39: - | L39: 5 Thn 8 Bln | M39: D-III | N39: AKBID Thn 2013 | O39: Kediri, 14-09-1992 | P39: Islam | Q39: Rani Rosita , Amd Keb
A40: 34 | B40: Rise Nisa' Meiula Naaifah | C40: 3506164105000001 | D40: PPPK-VII | E40: PPPK-PW | F40: 45962 | G40: Perekam Medis Terampil | H40: 44564 | I40: - | J40: - | K40: - | L40: 3 Thn 10 Bln | M40: D-III | N40: Rekam Medik Thn 2021 | O40: Kediri, 01-05-2000 | P40: Islam | Q40: Rise Nisa' Meiula Naaifah
A41: 35 | B41: Shalikul Hadi, SKM | C41: 3506161109000001 | D41: KONTRAK | F41: - | G41: PROMKES | H41: 44868 | I41: - | J41: - | K41: - | M41: S-1 | N41: SKM th. 22 | O41: Kediri, 07-09-2000 | P41: Islam | Q41: Shalikul Hadi, Skm
A42: 36 | B42: MUSTAINUL HABIBI | C42: 19871201 202421 1 018 | D42: PPPK-VII | E42: PPPK | F42: 45294 | G42: Perekam Medis Terampil | H42: 45294 | L42: 1 Thn 10 Bln | M42: D-III | N42: Rekam Medik | O42: Nganjuk, 01-12-1987 | P42: Islam | Q42: Mustainul Habibi
...

Sheet penjadwalan
A1: NO | B1: NAMA | C1: NIP / NIK | D1: GOL | E1: JENIS ASN | F1: NAMA JABATAN
A2: 1 | B2: dr.Durotun Nafisa | C2: 19750423 200212 2 005 | D2: Ivc | E2: PNS | F2: Dokter Ahli Madya
A3: 2 | B3: drg. Putri Emyta Sari | C3: 19810604 200902 2 004 | D3: Ivb | E3: PNS | F3: Dokter Gigi Ahli Madya
A4: 3 | B4: Setya Budi, Amd., Kep | C4: 19700508 199203 1 003 | D4: IIId | E4: PNS | F4: Perawat Ahli pertama
A5: 4 | B5: Luluk Listyaningsih,AMG | C5: 19691030 199203 2 008 | D5: IIId | E5: PNS | F5: Nutrisionis Penyelia
A6: 5 | B6: Yuanendah, SST. | C6: 19710125 199203 2 010 | D6: IIId | E6: PNS | F6: Bidan Ahli Muda
A7: 6 | B7: Daril Rahmatullah, S. Farm. | C7: 19810704 200901 1 004 | D7: Iva | E7: PNS | F7: Apoteker Ahli Madya
A8: 7 | B8: Fitri Ariani Isnaningtyas, Amd.AK | C8: 19780908 199903 2 001 | D8: IIId | E8: PNS | F8: Pranata Labkes Pelaksana Penyelia
A9: 8 | B9: Rinda Ari Puspita, Amd. KG | C9: 19871127 201001 2 008 | D9: IIIb | E9: PNS | F9: Terapis Gigi dan Mulut Mahir
A10: 9 | B10: dr. Rizky Rachmat Kurniawan | C10: 19960310 202203 1 005 | D10: IIIb | E10: PNS | F10: Dokter Pertama
A11: 10 | B11: Supatemi, Amd.Keb | C11: 19720306 200604 2 014 | D11: IIIb | E11: PNS | F11: Bidan Mahir
A12: 11 | B12: Anik Sri Purwati, Amd. Keb. | C12: 19740806 200604 2 022 | D12: IIIb | E12: PNS | F12: Bidan Mahir
A13: 12 | B13: Enny Nurhayati, Amd.. Keb. | C13: 19741101 200604 2 014 | D13: IIIb | E13: PNS | F13: Bidan Mahir
... A28: 27 | B28: Slamet Riadi | C28: 3506212005790003 | D28: PPPK-V | E28: PPPK-PW | F28: Operator Layanan Operasional
A29: 28 | B29: Anita Sumariati | C29: 3506214101850002 | D29: KONTRAK | F29: KEBERSIHAN
A30: 29 | B30: Mimin Asmawati | C30: 3506215707790002 | D30: KONTRAK | F30: KEBERSIHAN
A31: 30 | B31: Fitria Indriyani | C31: 3506215502970001 | D31: PPPK-V | E31: PPPK-PW | F31: Operator Layanan Operasional
A32: 31 | B32: Cendy Santia KS, Amd AK | C32: 3506154409920001 | D32: PPPK-VII | E32: PPPK-PW | F32: Pranata Labkes Terampil
A33: 32 | B33: Mistiani Saputri, Amd Kom | C33: 3506266204980003 | D33: PPPK-VII | E33: PPPK-PW | F33: Pengelola Layanan Operasional
A34: 33 | B34: Rani Rosita , Amd Keb | C34: 3506265409920003 | D34: PPPK-VII | E34: PPPK-PW | F34: Bidan Terampil
A35: 34 | B35: Rise Nisa' Meiula Naaifah | C35: 3506164105000001 | D35: PPPK-VII | E35: PPPK-PW | F35: Perekam Medis Terampil
A36: 35 | B36: Shalikul Hadi, SKM | C36: 3506161109000001 | D36: KONTRAK | F36: PROMKES
A37: 36 | B37: MUSTAINUL HABIBI | C37: 19871201 202421 1 018 | D37: PPPK-VII | E37: PPPK | F37: Perekam Medis Terampil
A38: 37 | B38: GALIH CATUR AJI SETIAWAN | C38: 19930220 202421 1 005 | D38: PPPK-X | E38: PPPK | F38: Dokter Ahli Pertama
A39: 38 | B39: BINTI KHOTIMATUL MUNAWAROH | C39: 19970129 202421 2 022 | D39: PPPK-VII | E39: PPPK | F39: Bidan Terampil
A40: 39 | B40: VIRDA NILAYANTI | C40: 199906292024212023 | D40: PPPK-VII | E40: PPPK | F40: Perawat Terampil
A41: 40 | B41: DELLA ANANDANI HAREFA | C41: 19950224 202421 2 013 | D41: PPPK-VII | E41: PPPK | F41: Perawat Terampil
A42: 41 | B42: FENIA ELDIANA | C42: 19970225 202521 2 007 | D42: PPPK-VII | E42: PPPK | F42: Pranata Labkes Terampil
A43: 42 | B43: Aide Bagus Lutfi Zakaria,A.Md.Kep | C43: '3518071503890005 | D43: KONTRAK | F43: Perawat Terampil
A44: 43 | B44: Wenly Novi Newanda,A.Md.Keb | C44: '3506114111970003 | D44: KONTRAK | F44: Bidan Terampil
A45: 44 | B45: Dwi Lestari,A.Md.Keb | C45: '3506216909940001 | D45: KONTRAK | F45: Bidan Terampil
A46: 45 | B46: ika Bintari, A.Md.Keb | C46: 19910519 202521 2 033 | D46: PPPK-VII | E46: PPPK | F46: Bidan Terampil
A47: 46 | B47: Ronal Ardianto | C47: 3506210301020001 | D47: KONTRAK | F47: cs
A48: 47 | B48: Rinda Agustina,Amd.Gizi | C48: 3506216208960001 | D48: KONTRAK | F48: Nutrisionis Terampil
A49: 48 | B49: Yogi Satrio Lelono | C49: 3506210306030002 | D49: KONTRAK | F49: Perawat Terampil

Sheet DUK 2022
A1: DAFTAR URUT KEPEGAWAIAN
A2: UPTD PUSKESMAS KUNJANG
A3: PER 28 Februari 2023
A5: NO | B5: NAMA | C5: NIP / NIK | D5: GOL | E5: TMT | F5: NAMA | G5: TMT | H5: ESE | I5: MASA KERJA | K5: DIKLAT | L5: PEN | M5: KETERANGAN | N5: TEMPAT | O5: AGAMA | P5: KET
E6: GLNGAN | F6: JABATAN | G6: JABATAN | H6: LON | I6: THN | J6: BLN | L6: DDK | M6: PENDIDIKAN | N6: TANGGAL LAHIR
A7: 1 | B7: dr.Durotun Nafisa | C7: 19750423 200212 2 005 | D7: Ivc | E7: 44835 | F7: Dokter Ahli Madya | G7: 42606 | H7: IV/c | I7: 22 | J7: 0 | K7: - | L7: S1 | M7: Dokter Umum Th 1999 | N7: Kediri, 23-04-1975 | O7: Islam | P7: Fungsional Tertentu
A8: 2 | B8: drg. Putri Emyta Sari | C8: 19810604 200902 2 004 | D8: Ivb | E8: 45017 | F8: Dokter Gigi Ahli Madya | G8: 45017 | H8: - | I8: 13 | J8: 5 | K8: - | L8: S1 | M8: FKG Th. 2006 | N8: Kediri, 04-06-1981 | O8: Islam | P8: Fungsional Tertentu
A9: 3 | B9: Jema’I, Amd.. Keb. | C9: 19671215 198811 2 002 | D9: IIId | E9: 41548 | F9: Administrasi Umum | G9: 41548 | H9: - | I9: 28 | J9: 8 | K9: - | L9: D III | M9: AKBID Thn 2007 | N9: Kediri, 15-12-1967 | O9: Islam | P9: Fungsional Tertentu
A10: 4 | B10: Setya Budi, Amd., Kep | C10: 19700508 199203 1 003 | D10: IIId | E10: 42278 | F10: Perawat Penyelia | G10: 42278 | H10: - | I10: 25 | J10: 4 | K10: - | L10: D III | M10: AKPER Thn 2004 | N10: Kediri, 08-05-1970 | O10: Islam | P10: Fungsional Tertentu
A11: 5 | B11: Luluk Listyaningsih,AMG | C11: 19691030 199203 2 008 | D11: IIId | E11: 42644 | F11: Nutrisionis Penyelia | G11: 42644 | H11: - | I11: 25 | J11: 4 | K11: - | L11: D III | M11: AKZI Thn 2003 | N11: Kediri, 30-10-1969 | O11: Islam | P11: Fungsional Tertentu
A12: 6 | B12: Yuanendah, SST. | C12: 19710125 199203 2 010 | D12: IIId | E12: 44470 | F12: Bidan Ahli Muda | G12: 42712 | H12: - | I12: 25 | J12: 4 | K12: - | L12: D IV | M12: Bidan Pendidik Thn 2013 | N12: Kediri, 25-01-1971 | O12: Islam | P12: Fungsional Tertentu
A13: 7 | B13: Daril Rahmatullah, S. Farm. | C13: 19810704 200901 1 004 | D13: Iva | E13: 45627 | F13: Apoteker Ahli Madya | G13: 45544 | H13: - | I13: 15 | J13: 11 | K13: - | L13: S1 | M13: Apoteker Thn 2005 | N13: Nganjuk, 04-07-1981 | O13: Islam | P13: Fungsional Tertentu
A14: 8 | B14: Fitri Ariani Isnaningtyas, Amd.AK | C14: 19780908 199903 2 001 | D14: IIIc | E14: 44470 | F14: Pranata Labkes Pelaksana Penyelia | G14: - | H14: - | I14: 18 | J14: 3 | K14: - | L14: D III | M14: Anls Kesh Thn 2009 | N14: Kediri, 08-09-1978 | O14: Islam | P14: Fungsional Tertentu
A15: 9 | B15: Rinda Ari Puspita, Amd. KG | C15: 19871127 201001 2 008 | D15: IIIb | E15: 44652 | F15: Terapis Gigi dan Mulut Mahir | G15: 44652 | H15: - | I15: 10 | J15: 5 | K15: - | L15: D III | M15: Kesh.Gigi Thn 2009 | N15: Jombang, 27-11-1987 | O15: Islam | P15: Fungsional Tertentu
A16: 10 | B16: dr. Rizky Rachmat Kurniawan | C16: 19960310 202203 1 005 | D16: III/b | E16: 44621 | F16: Dokter Pertama | G16: - | H16: - | I16: - | J16: 3 | K16: - | L16: S1 | M16: Dokter Umum Th 2019 | N16: Samarinda,10-03-1996 | O16: Islam | P16: Fungsional Tertentu
A17: 11 | B17: Supatemi, Amd.Keb | C17: 19720306 200604 2 014 | D17: IIIa | E17: 44470 | F17: Bidan Mahir | G17: 44279 | H17: - | I17: 22 | J17: 8 | K17: - | L17: D III | M17: AKBID Thn 2005 | N17: Kediri, 06-03-1972 | O17: Islam | P17: Fungsional Tertentu
A18: 12 | B18: Anik Sri Purwati, Amd. Keb. | C18: 19740806 200604 2 022 | D18: IIIa | E18: 44470 | F18: Bidan Mahir | G18: 44279 | H18: - | I18: 22 | J18: 8 | K18: - | L18: D III | M18: AKBID Thn 2009 | N18: Kediri, 06-08-1974 | O18: Islam | P18: Fungsional Tertentu
A19: 13 | B19: Enny Nurhayati, Amd.. Keb. | C19: 19741101 200604 2 014 | D19: IIIa | E19: 44470 | F19: Bidan Mahir | G19: 44279 | H19: - | I19: 23 | J19: 8 | K19: - | L19: D III | M19: AKBID Thn 2009 | N19: Jombang, 01-11-1974 | O19: Islam | P19: Fungsional Tertentu
A20: 14 | B20: Sulisni, Amd. Keb. | C20: 19750315 200604 2 031 | D20: IIIa | E20: 44470 | F20: Bidan Mahir | G20: 44279 | H20: - | I20: 23 | J20: 8 | K20: - | L20: D III | M20: AKBID Thn 2012 | N20: Jombang, 15-03-1975 | O20: Islam | P20: Fungsional Tertentu
A21: 15 | B21: Estu Rahayuningsih, Amd. Keb. | C21: 19751117 200701 2 010 | D21: IIIa | E21: 44835 | F21: Bidan Pelaksana Lanutan | G21: - | H21: - | I21: 22 | J21: 2 | K21: - | L21: D III | M21: AKBID Thn 2012 | N21: Pati, 17-11-1975 | O21: Kristen | P21: Fungsional Tertentu
A22: 16 | B22: Prihatiningtyas, Amd. Keb. | C22: 19760521 200701 2 012 | D22: IIIa | E22: 44835 | F22: Bidan Pelaksana Lanjutan | G22: - | H22: - | I22: 22 | J22: 2 | K22: - | L22: D III | M22: AKBID Thn 2012 | N22: Kediri, 21-05-1976 | O22: Islam | P22: Fungsional Tertentu
A23: 17 | B23: Mey Idayati, Amd.Kep | C23: 19870507 201402 2 001 | D23: IIIb | E23: 45200 | F23: Perawat Mahir | G23: 43922 | H23: - | I23: 10 | J23: 4 | K23: - | L23: D III | M23: Keperawatan, 2010 | N23: Kediri, 07-05-1987 | O23: Islam | P23: Fungsional Tertentu
A24: 18 | B24: Sito Luncono Setio Utomo | C24: 19790506 201001 1 027 | D24: lld | E24: 44652 | F24: Staf | H24: - | I24: 17 | J24: 8 | K24: - | L24: SLTA | M24: SMA Thn. | N24: Surabaya, 06-05-1979 | O24: Islam | P24: Fungsional Tertentu
A25: 19 | B25: Siti Aminah, Amd Kep. | C25: 19870803 201903 2 005 | D25: Iid | E25: 44835 | F25: Perawat Terampil | G25: - | H25: - | I25: 6 | J25: 9 | K25: - | L25: DIII | M25: AKPER Thn 2009 | N25: Kediri,03-08-1987 | O25: Islam | P25: Fungsional Tertentu
A26: 20 | B26: Nuryana Vidya C, Amd.Kep | C26: 19970326 202012 2 013 | D26: llc | E26: 44166 | F26: Perawat Terampil | G26: 44531 | H26: - | I26: 4 | J26: 6 | K26: - | L26: D III | M26: AKPER Thn.2018 | N26: Kediri, 26-03-1997 | O26: Islam | P26: Fungsional Tertentu
A27: 21 | B27: Novia Anjarwati, Amd. Kes | C27: 19951125 202012 2 013 | D27: llc | E27: 44166 | F27: Sanitarian Pelaksana | G27: 44531 | H27: - | I27: 4 | J27: 6 | K27: - | L27: D III | M27: Kesling Thn. 2018 | N27: Nganjuk, 25-11-1995 | O27: Islam | P27: Fungsional Tertentu
A28: 22 | B28: Dinung Wahyu Purwanti | C28: 19930105 202221 2 001 | D28: VII | E28: 44562 | F28: Bidan Terampil | G28: 44562 | I28: - | J28: 5 | K28: - | L28: D III | M28: Bidan Terampil | N28: Kediri, 05- 01-1993 | O28: Islam
A29: 23 | B29: Susi Winda Wandari, Amd Keb | C29: 19940405 202321 2 005 | D29: VII | E29: - | F29: Bidan Terampil | G29: 45017 | H29: - | I29: - | J29: - | K29: - | L29: D-III | M29: AKBID Thn 2015 | N29: Kediri, 05-04-1994 | O29: Islam
A30: 24 | B30: Desi Natalia, SST | C30: 3506216412890001 | D30: - | E30: - | F30: BIDAN DESA | G30: 42370 | H30: - | I30: - | J30: - | K30: - | L30: D-IV | M30: Kebidanan Thn. 2011 | N30: Kediri, 24-12-1989 | O30: Islam
A31: 25 | B31: Devi Ardianti, SE | C31: 3506164503950002 | D31: - | E31: - | F31: AKUNTANSI BOK | G31: 42758 | H31: - | I31: - | J31: - | K31: - | L31: S-1 | M31: Akuntansi Thn 2016 | N31: Kediri, 05-03-1995 | O31: Islam
A32: 26 | B32: Vivi Juni Mega A, S.Tr.Keb | C32: 3506214506950001 | D32: - | E32: - | F32: BIDAN DESA | G32: 43497 | H32: - | I32: - | J32: - | K32: - | L32: D-IV | M32: AKBID Thn.2013 | N32: Kediri, 05-06-1995 | O32: Islam
A33: 27 | B33: Anieta Yuni Purnawati, Amd.Keb | C33: 3506215706900001 | D33: - | E33: - | F33: BIDAN DESA | G33: 42410 | H33: - | I33: - | J33: - | K33: - | L33: D-III | M33: AKBID Thn 2017 | N33: Kediri, 17-06-1990 | O33: Islam
A34: 28 | B34: Della Karisma Lutfiana, Amd. Gz | C34: 3506144604970001 | D34: - | E34: - | F34: NUTRISIONIS | G34: 43497 | H34: - | I34: - | J34: - | K34: - | L34: D-III | M34: AKZI Thn 2018 | N34: Kediri, 06-04-1997 | O34: Islam
A35: 29 | B35: Slamet Riadi | C35: 3506212005790003 | D35: - | E35: - | F35: KEBERSIHAN/ SOPIR | G35: 35643 | H35: - | I35: - | J35: - | K35: - | L35: SMA | M35: Thn 2008 | N35: Kediri, 20-05-1979 | O35: Islam
A36: 30 | B36: Anita Sumariati | C36: 3506214101850002 | D36: - | E36: - | F36: KEBERSIHAN | G36: 43101 | H36: - | I36: - | J36: - | K36: - | L36: SMP | M36: Thn 2000 | N36: Madiun, 02-01-1985 | O36: Islam
A37: 31 | B37: Mimin Asmawati | C37: 3506215707790002 | D37: - | E37: - | F37: KEBERSIHAN | G37: 01/01/2020 | H37: - | I37: - | J37: - | K37: - | L37: SMK | M37: Thn 1999 | N37: Kediri, 17-07-1979 | O37: Islam
A38: 32 | B38: Shindy Erlina Putri Pramujib | C38: 3506166906960001 | D38: - | E38: - | F38: LOKET/ADMINISTRASI UMUM | G38: 42491 | H38: - | I38: - | J38: - | K38: - | L38: S1 | M38: Akuntasi Thn 2021 | N38: Kediri, 29-06-1996 | O38: Islam
A39: 33 | B39: Fitria Indriyani | C39: 3506215502970001 | D39: - | E39: - | F39: ASISTEN APOTEKER | G39: 43222 | H39: - | I39: - | J39: - | K39: - | L39: D-1 | M39: Manajemen Farmasi Thn 2017 | N39: Kediri, 15-02-1997 | O39: Islam
A40: 34 | B40: Cendy Santia KS, Amd AK | C40: 3506154409920001 | D40: - | E40: - | F40: ANALIS KESEHATAN | G40: 43832 | H40: - | I40: - | J40: - | K40: - | L40: D-III | M40: Analis Kesh Thn 2016 | N40: Analis Kesh Thn 2016 | O40: Islam
A41: 35 | B41: Mistiani Saputri, Amd Kom | C41: 3506266204980003 | D41: - | E41: - | F41: ADMINISTRASI UMUM | G41: 44256 | H41: - | I41: - | J41: - | K41: - | L41: D-III | M41: Manajemen Informatika Thn. 2019 | N41: Kediri, 22-04-1998 | O41: Islam
...

Sheet Pangkat
A1: DAFTAR KENAIKAN PANGKAT PEGAWAI
A2: UPTD PUSKESMAS KUNJANG
A4: No | B4: Nama | C4: Gol | D4: TMT | E4: Masa Kerja | G4: Waktu Pengusulan Kenaikan Pangkat
E5: Tahun | F5: Bulan
A6: 1 | B6: dr.Durotun Nafisa | C6: IVc | D6: 44844 | E6: 21 | F6: 10
A7: 2 | B7: drg. Putri Emyta Sari | C7: Ivb | D7: 45017 | E7: 14 | F7: 2 | G7: Ivc | H7: 46296
A8: 3 | B8: Jema’I, Amd.. Keb. | C8: IIId | D8: 41548 | E8: 19 | F8: 11
A9: 4 | B9: Setya Budi, Amd., Kep | C9: IIId | D9: 42278 | E9: 18 | F9: 7 | G9: IVa | H9: 45200
A10: 5 | B10: Luluk Listyaningsih,AMG | C10: IIId | D10: 42644 | E10: 19 | F10: 7
A11: 6 | B11: Yuanendah, SST. | C11: IIId | D11: 44470 | E11: 24 | F11: 7 | G11: IVa | H11: 45748
A12: 7 | B12: Daril Rahmatullah, S. Farm. | C12: Iva | D12: 43922 | E12: 11 | F12: 3 | G12: IVa | H12: 45200
A13: 8 | B13: Fitri Ariani Isnaningtyas, Amd.AK | C13: IIIc | D13: 44470 | E13: 17 | F13: 7 | G13: IIId | H13: 45748
A14: 9 | B14: Rinda Ari Puspita, Amd. KG | C14: IIIb | D14: 44652 | E14: 10 | F14: 3 | G14: IIIc | H14: 45931
A15: 10 | B15: dr. Rizky Rachmat Kurniawan | C15: IIIb | D15: 44986 | E15: 1 | F15: 0 | G15: IIIc | H15: 45931
A16: 11 | B16: Supatemi, Amd.Keb | C16: IIIa | D16: 44470 | E16: 22 | F16: 0 | G16: IIIb | H16: 45748
A17: 12 | B17: Anik Sri Purwati, Amd. Keb. | C17: IIIa | D17: 44470 | E17: 22 | F17: 0 | G17: IIIb | H17: 45748
A18: 13 | B18: Enny Nurhayati, Amd.. Keb. | C18: IIIa | D18: 44470 | E18: 23 | F18: 0 | G18: IIIb | H18: 45748
A19: 14 | B19: Sulisni, Amd. Keb. | C19: IIIa | D19: 44470 | E19: 21 | F19: 0 | G19: IIIb | H19: 45748
A20: 15 | B20: Estu Rahayuningsih, Amd. Keb. | C20: IIIa | D20: 44835 | E20: 22 | F20: 0 | G20: IIIb | H20: 46113
A21: 16 | B21: Prihatiningtyas, Amd. Keb. | C21: IIIa | D21: 44835 | E21: 22 | F21: 0 | G21: IIIb | H21: 46113
A22: 17 | B22: Mey Idayati, Amd.Kep | C22: IIIb | D22: 45200 | E22: 10 | F22: 4 | G22: IIIc | H22: 46478
... A26: 21 | B26: Novia Anjarwati, Amd. Kes | C26: Iid | D26: 45444 | E26: 6 | F26: 6 | G26: IIIa | H26: 46753

Sheet KGB
A1: REGISTER PENJAGAAN KENAIKNAN GAJI BERKALA
A2: UPTD PUSKESMAS KUNJANG
A4: No | B4: Nama | C4: NIP | D4: Gol | E4: KGB Terakhir | F4: Masa Kerja | H4: Pengusulan KGB | I4: Masa Kerja
F5: Thn | G5: Bln | I5: Thn | J5: Bln
A6: 1 | B6: dr.Durotun Nafisa | C6: 19750423 200212 2 005 | D6: Ivc | E6: 45627 | F6: 24 | G6: 0 | H6: 46357 | I6: 26 | J6: 0
A7: 2 | B7: drg. Putri Emyta Sari | C7: 19810604 200902 2 004 | D7: Ivb | E7: 44958 | F7: 14 | G7: 0 | H7: 45689 | I7: 16 | J7: 0
A8: 3 | B8: Jema’I, Amd.. Keb. | C8: 19671215 198811 2 002 | D8: IIId | E8: 45231 | F8: 30 | G8: 0 | H8: 45962 | I8: 32 | J8: 0
A9: 4 | B9: Setya Budi, Amd., Kep | C9: 19700508 199203 1 003 | D9: IIId | E9: 44986 | F9: 26 | G9: 0 | H9: 45717 | I9: 28 | J9: 0
A10: 5 | B10: Luluk Listyaningsih,AMG | C10: 19691030 199203 2 008 | D10: IIId | E10: 44986 | F10: 26 | G10: 0 | H10: 45717 | I10: 28 | J10: 0
A11: 6 | B11: Yuanendah, SST. | C11: 19710125 199203 2 010 | D11: IIId | E11: 44986 | F11: 26 | G11: 0 | H11: 46296 | I11: 28 | J11: 0
A12: 7 | B12: Daril Rahmatullah, S. Farm. | C12: 19810704 200901 1 004 | D12: Iva | E12: 45658 | F12: 16 | G12: 0 | H12: 46388 | I12: 18 | J12: 0
A13: 8 | B13: Fitri Ariani Isnaningtyas, Amd.AK | C13: 19780908 199903 2 001 | D13: IIIc | E13: 45352 | F13: 20 | G13: 0 | H13: 46082 | I13: 22 | J13: 0
A14: 9 | B14: Rinda Ari Puspita, Amd. KG | C14: 19871127 201001 2 008 | D14: IIIb | E14: 44563 | F14: 10 | G14: 0 | H14: 45293 | I14: 12 | J14: 0
A15: 10 | B15: dr. Rizky Rachmat Kurniawan | C15: 19960310 202203 1 005 | D15: III/b | E15: 45352 | F15: 2 | G15: 0 | H15: 46082 | I15: 4 | J15: 0 | N15: 198107042009011004
A16: 11 | B16: Supatemi, Amd.Keb | C16: 19720306 200604 2 014 | D16: IIIa | E16: 45200 | F16: 24 | G16: 0 | H16: 45931 | I16: 26 | J16: 0
A17: 12 | B17: Anik Sri Purwati, Amd. Keb. | C17: 19740806 200604 2 022 | D17: IIIa | E17: 45200 | F17: 24 | G17: 0 | H17: 45931 | I17: 26 | J17: 0
A18: 13 | B18: Enny Nurhayati, Amd.. Keb. | C18: 19741101 200604 2 014 | D18: IIIa | E18: 45566 | F18: 26 | G18: 0 | H18: 46296 | I18: 28 | J18: 0
A19: 14 | B19: Sulisni, Amd. Keb. | C19: 19750315 200604 2 031 | D19: IIIa | E19: 45566 | F19: 24 | G19: 0 | H19: 46296 | I19: 26 | J19: 0
A20: 15 | B20: Estu Rahayuningsih, Amd. Keb. | C20: 19751117 200701 2 010 | D20: IIIa | E20: 45566 | F20: 24 | G20: 0 | H20: 46296 | I20: 26 | J20: 0 | N20: 55918
A21: 16 | B21: Prihatiningtyas, Amd. Keb. | C21: 19760521 200701 2 012 | D21: IIIa | E21: 45566 | F21: 24 | G21: 0 | H21: 46296 | I21: 26 | J21: 0 | N21: 69886
A22: 17 | B22: Mey Idayati, Amd.Kep | C22: 19870507 201402 2 001 | D22: IIIa | E22: 45078 | F22: 10 | G22: 0 | H22: 45809 | I22: 12 | J22: 0 | N22: =SUM(N20:N21) -> 125804
A23: 18 | B23: Sito Luncono Setio Utomo | C23: 19790506 201001 1 027 | D23: lld | E23: 45200 | F23: 19 | G23: 0 | H23: 45931 | I23: 21 | J23: 0
A24: 19 | B24: Siti Aminah, Amd Kep. | C24: 19870803 201903 2 005 | D24: lld | E24: 44986 | F24: 7 | G24: 0 | H24: 45717 | I24: 9 | J24: 0
A25: 20 | B25: Nuryana Vidya C, Amd.Kep | C25: 19970326 202012 2 013 | D25: lld | E25: 45627 | F25: 7 | G25: 0 | H25: 46357 | I25: 9 | J25: 0
A26: 21 | B26: Novia Anjarwati, Amd. Kes | C26: 19951125 202012 2 013 | D26: lld | E26: 45627 | F26: 7 | G26: 0 | H26: 46357 | I26: 9 | J26: 0
A27: 22 | B27: Dinung Wahyu Purwanti, A.Md | C27: 19930105 202221 2 001 | D27: VII | E27: 45292 | F27: 5 | G27: 0 | H27: 46023 | I27: 7 | J27: 0
A28: 23 | B28: Susi Winda Wandari, Amd Keb | C28: 19940405 202321 2 005 | D28: VII
A29: 24 | B29: dr, Galih Catur Aji Setiawan | C29: 19930220 202421 1 005 | D29: X
A30: 25 | B30: Musta'inul Habibi | C30: 19871201 202421 1 018 | D30: VII
A31: 26 | B31: Binti Khotimatul Munawaroh, A.Md.Keb | C31: 19970129 202421 2 022 | D31: VII
A32: 27 | B32: Della Anandani Harefa, Amd.Kep | C32: 19950224 202421 2 013 | D32: VII
A33: 28 | B33: Virda Nilayanti | C33: 19990629 202421 2 023 | D33: VII
A34: 29 | B34: Anieta Yuni Purnawati, Amd.Keb | C34: 19900617 202421 2 004 | D34: VII

Sheet Deal
A3: No | B3: Nama | C3: Tempat Lahir | D3: Tgl Lahir | E3: Pendidikan | F3: Jabatan | G3: Nip / Nik | H3: TMT CPNS | I3: TMT PNS | J3: GOL | K3: TMT | L3: Masa Kerja | N3: STR | P3: SIP | R3: Ket
K4: Gol Terakhir | L4: Tahun | M4: Bulan | N4: Nomer | O4: Berlaku | P4: Nomer | Q4: Berlaku
A5: 1 | B5: dr.Durotun Nafisa | C5: Kediri | D5: 23-04-1975 | E5: S1 | F5: Dokter Ahli Madya | G5: 19750423 200212 2 005 | H5: 37591 | I5: 38078 | J5: Ivc | K5: 44835 | L5: 21 | M5: 10 | N5: 35 2 1 100 4 22 012392 | O5: 46500 | P5: 446/3247/418.25/2022 | Q5: 46500 | R5: Berkas STR belum ada
A6: 2 | B6: drg. Putri Emyta Sari | C6: Kediri | D6: 04-06-1981 | E6: S1 | F6: Dokter Gigi Ahli Madya | G6: 19810604 200902 2 004 | H6: 39845 | I6: 40544 | J6: Ivb | K6: 45017 | L6: 14 | M6: 2 | N6: 3.5221004e+15 | O6: 46542 | P6: 446/5418/418.25/2022 | Q6: 46542 | S6: 3.5221004e+15
A7: 3 | B7: Jema’I, Amd.. Keb. | C7: Kediri | D7: 15-12-1967 | E7: D III | F7: Administrasi Umum | G7: 19671215 198811 2 002 | H7: 32448 | I7: 33178 | J7: IIId | K7: 41548 | L7: 19 | M7: 11 | N7: 16 02 5 2 2 22-4473580 | O7: 46736 | P7: 446/17418/418.25/2022 | Q7: 46736
A8: 4 | B8: Setya Budi, Amd., Kep | C8: Kediri | D8: 08-05-1970 | E8: D III | F8: Perawat Penyelia | G8: 19700508 199203 1 003 | H8: 33664 | I8: 34394 | J8: IIId | K8: 42278 | L8: 18 | M8: 7 | N8: 16 01 7 2 2 22-4376440 | O8: 46515 | P8: 446/13309/418.25/2022 | Q8: 46515
A9: 5 | B9: Luluk Listyaningsih,AMG | C9: Kediri | D9: 30-10-1969 | E9: D III | F9: Nutrisionis Penyelia | G9: 19691030 199203 2 008 | H9: 33664 | J9: IIId | K9: 42644 | L9: 19 | M9: 7 | N9: P2T/63/03/.10/02/11/2018 | O9: 45229 | P9: 446/16.410/418.25/2018 | Q9: 45229
A10: 6 | B10: Yuanendah, SST. | C10: Kediri | D10: 25958 | E10: D IV | F10: Bidan Ahli Muda | G10: 19710125 199203 2 010 | H10: 33664 | I10: 34394 | J10: IIId | K10: 44470 | L10: 24 | M10: 7 | N10: 16 02 6 2 2 22-4545675 | O10: 46412 | R10: SIP belum ada
A11: 7 | B11: Daril Rahmatullah, S. Farm. | C11: Nganjuk | D11: 29771 | E11: S1 | F11: Apoteker Ahli Muda | G11: 19810704 200901 1 004 | H11: 39814 | I11: 40513 | J11: IIId | K11: 43922 | L11: 11 | M11: 3 | N11: 19810704/STRA-UGM/2005/12051 | O11: 46207 | P11: 19810704/SIPA-35.06/2021/1162 | Q11: 46207
A12: 8 | B12: Fitri Ariani Isnaningtyas, Amd.AK | C12: Kediri | D12: 08-09-1978 | E12: D III | F12: Pranata Labkes Pelaksana Penyelia | G12: 19780908 199903 2 001 | H12: 36220 | I12: 36892 | J12: IIIc | K12: 44470 | L12: 17 | M12: 7 | N12: 16 14 5 2 2 17-2135509 | O12: 44812 | P12: 446/19671/418.25/2020 | Q12: 44812 | R12: STR dan SIP Mati
A13: 9 | B13: Umi Kulsum | C13: Sidoarjo | D13: 09-09-1966 | E13: SLTA | F13: Pengadministrasi Umum | G13: 19660909 198801 2 002 | H13: 32143 | I13: 33420 | J13: IIIb | K13: 39904 | L13: 16 | M13: 3
A14: 10 | B14: Rinda Ari Puspita, Amd. KG | C14: Jombang | D14: 27-11-1987 | E14: D III | F14: Terapis Gigi dan Mulut | G14: 19871127 201001 2 008 | H14: 40179 | I14: 40878 | J14: IIIb | L14: 10 | M14: 3 | N14: 16 04 5 2 2 22-4497124 | O14: 46718 | P14: 446/9618/418.25/2019 | Q14: 44892 | R14: SIP Mati
A15: 11 | B15: dr. Rizky Rachmat Kurniawan | C15: Samarinda | D15: 35134 | E15: S1 | F15: Dokter Pertama | G15: 19960310 202203 1 005 | H15: 44621 | I15: 44986 | J15: III/b | K15: 44986 | L15: 1 | M15: 0 | N15: 3.5111001e+15 | O15: 45361 | P15: 446/4821/418.25/2022 | Q15: 45361
A16: 12 | B16: Supatemi, Amd.Keb | C16: Kediri | D16: 06-03-1972 | E16: D III | F16: Bidan Mahir | G16: 19720306 200604 2 014 | H16: 38808 | I16: 39539 | J16: IIIa | K16: 44470 | L16: 22 | M16: 0 | N16: 16 02 6 2 2 23-4572343 | O16: 46818 | P16: 446/2431/418.25/2020 | Q16: 44626 | R16: SIP Mati
A17: 13 | B17: Anik Sri Purwati, Amd. Keb. | C17: Kediri | D17: 06-08-1974 | E17: D III | F17: Bidan Mahir | G17: 19740806 200604 2 022 | H17: 38808 | I17: 39539 | J17: IIIa | K17: 44470 | L17: 22 | M17: 0 | N17: 16 02 5 2 2 22-4468115 | O17: 46605 | P17: 446/17079/418.25/2022 | Q17: 06/082027
A18: 14 | B18: Enny Nurhayati, Amd.. Keb. | C18: Jombang | D18: 27334 | E18: D III | F18: Bidan Mahir | G18: 19741101 200604 2 014 | H18: 38808 | I18: 39539 | J18: IIIa | K18: 44470 | L18: 23 | M18: 0 | N18: 16 02 5 2 2 22-4533496 | O18: 46692 | P18: 446/1315/418.25/2023 | Q18: 46692
A19: 15 | B19: Sulisni, Amd. Keb. | C19: Jombang | D19: 15-03-1975 | E19: D III | F19: Bidan Mahir | G19: 19750315 200604 2 031 | H19: 38808 | I19: 39539 | J19: IIIa | K19: 44470 | L19: 21 | M19: 0 | N19: 16 02 5 2 2 22-4258495 | O19: 46461 | P19: 446/6909/418.25/2022 | Q19: 46461
A20: 16 | B20: Estu Rahayuningsih, Amd. Keb. | C20: Pati | D20: 17-11-1975 | E20: D III | F20: Bidan Pelaksana Lanutan | G20: 19751117 200701 2 010 | H20: 39083 | I20: 39995 | J20: IIIa | K20: 44835 | L20: 22 | M20: 0 | N20: 16 02 5 2 2 22-4503131 | O20: 46708 | P20: 446/183/418.25/2023 | Q20: 46708
A21: 17 | B21: Prihatiningtyas, Amd. Keb. | C21: Kediri | D21: 21-05-1976 | E21: D III | F21: Bidan Pelaksana Lanjutan | G21: 19760521 200701 2 012 | H21: 39083 | I21: 39995 | J21: IIIa | K21: 44835 | L21: 22 | M21: 0 | N21: 16 02 5 2 1 17-2096355 | O21: 44702 | P21: 446/21.304/418.25/2018 | Q21: 44702 | R21: STR dan SIP Mati
A22: 18 | B22: Mey Idayati, Amd.Kep | C22: Kediri | D22: 07-05-1987 | E22: D III | F22: Perawat Mahir | G22: 19870507 201402 2 001 | H22: 41671 | I22: 42095 | J22: IIIb | K22: 45200 | L22: 10 | M22: 4 | N22: 16 01 5 2 2 21-4011045 | O22: 46149 | P22: KS.06/1813/418.25/2023 | Q22: 46149
A23: 19 | B23: Istikaroh | C23: Kediri | D23: 23907 | E23: SLTA | F23: Pengadministrasi Umum | G23: 19650614 199203 2 007 | H23: 33664 | J23: IId | K23: 42461 | L23: 21 | M23: 1
A24: 20 | B24: Sito Luncono Setio Utomo | C24: Surabaya | D24: 06-05-1979 | E24: SLTA | F24: Pengadministrasi Kepegawaian | G24: 19790506 201001 1 027 | H24: 40179 | I24: 40909 | J24: lld | K24: 44652 | L24: 17 | M24: 6
A25: 21 | B25: Siti Aminah, Amd Kep. | C25: Kediri | D25: 31992 | E25: DIII | F25: Perawat Terampil | G25: 19870803 201903 2 005 | H25: 43525 | I25: 44044 | J25: Iid | K25: 44835 | L25: 6 | M25: 7 | N25: 16 01 5 2 2 19-3076593 | O25: 45507 | P25: 446/1334/418.25/2020 | Q25: 45507
A26: 22 | B26: Nuryana Vidya C, Amd.Kep | C26: Kediri | D26: 26-03-1997 | E26: D III | F26: Perawat Pelaksana | G26: 19970326 202012 2 013 | H26: 44166 | I26: 44621 | J26: llc | K26: 44621 | L26: 4 | M26: 3 | N26: 16 01 5 2 1 19-3056011 | O26: 45377 | P26: 446/20242/418.25/2022 | Q26: 45377
A27: 23 | B27: Novia Anjarwati, Amd. Kes | C27: Nganjuk | D27: 35028 | E27: D III | F27: Sanitarian Pelaksana | G27: 19951125 202012 2 013 | H27: 44166 | I27: 44621 | J27: llc | K27: 44621 | L27: 4 | M27: 3 | N27: 16 12 5 2 1 18-1578599 | O27: 45255 | R27: SIP Proses Pengurusan
A28: 24 | B28: Dinung Wahyu Purwanti | C28: Kediri | D28: 33974 | E28: D III | F28: Bidan Terampil | G28: 19930105 202221 2 001 | H28: 43862 | I28: 44621 | J28: VII | K28: 44562 | L28: - | M28: 5 | N28: 16 02 5 2 1 19-3055219 | O28: 45296 | P28: 446/1616/418.25/2022 | Q28: 45296
A29: 25 | B29: Susi Winda Wandari, Amd Keb | C29: Kediri | D29: 34429 | E29: D-III | F29: Bidan Terampil | G29: 19940405 202321 2 005 | H29: 45017 | I29: - | J29: VII | K29: - | L29: - | M29: - | N29: 16 02 5 2 2 22-1195615 | O29: 46117 | P29: 446/11556/418.25/2022 | Q29: 46117
A30: 26 | B30: Desi Natalia, SST | C30: Kediri | D30: 32866 | E30: D IV | G30: 3506216412890001 | H30: - | I30: - | J30: - | K30: - | L30: - | M30: - | N30: 16 02 5 2 2 23-4622522 | O30: 47111 | P30: KS.06/1440/418.25/2023 | Q30: 47111
A31: 27 | B31: Devi Ardianti, SE | C31: Kediri | D31: 34763 | E31: S 1 | G31: 3506164503950002 | H31: - | I31: - | J31: - | K31: - | L31: - | M31: -
A32: 28 | B32: Vivi Juni Mega A, S.Tr.Keb | C32: Kediri | D32: 34855 | E32: D IV | G32: 3506214506950001 | H32: - | I32: - | J32: - | K32: - | L32: - | M32: - | N32: 16 02 5 2 1 19-3161528 | O32: 45448 | P32: 446/1344/418.25/2020 | Q32: 45448
A33: 29 | B33: Anieta Yuni Purnawati, Amd.Keb | C33: Kediri | D33: 33041 | E33: D III | G33: 3506215706900001 | H33: - | I33: - | J33: - | K33: - | L33: - | M33: - | N33: 16 02 5 2 1 19-2426282 | O33: 45460 | P33: 446/19.141/418.25/2019 | Q33: 45460
A34: 30 | B34: Della Karisma Lutfiana, Amd. Gz | C34: Kediri | D34: 35526 | E34: D III | G34: 3506144604970001 | H34: - | I34: - | J34: - | K34: - | L34: - | M34: - | N34: 16 09 5 2 1 18-2390027 | O34: 45022 | P34: 446/18.069/418.25/2019 | Q34: 45022 | R34: STR dan SIP Mati
A35: 31 | B35: Slamet Riadi | C35: Kediri | D35: 28995 | E35: SMA | G35: 3506212005790003 | H35: - | I35: - | J35: - | K35: - | L35: - | M35: -
A36: 32 | B36: Anita Sumariati | C36: Madiun | D36: 31049 | E36: SMP | G36: 3506214101850002 | H36: - | I36: - | J36: - | K36: - | L36: - | M36: -
A37: 33 | B37: Mimin Asmawati | C37: Kediri | D37: 29053 | E37: SMK | G37: 3506215707790002 | H37: - | I37: - | J37: - | K37: - | L37: - | M37: -
A38: 34 | B38: Shindy Erlina Putri Pramujib | C38: Kediri | D38: 35245 | E38: S1 | G38: 3506166906960001 | H38: - | I38: - | J38: - | K38: - | L38: - | M38: -
A39: 35 | B39: Fitria Indriyani | C39: Kediri | D39: 35476 | E39: D-1 | G39: 3506215502970001 | H39: - | I39: - | J39: - | K39: - | L39: - | M39: - | R39: STR dan SIP belum ada
A40: 36 | B40: dr. Moch. Edwin Adriyanto | C40: Kediri | D40: 30298 | E40: S-1 | G40: 3506131312820001 | H40: - | I40: - | J40: - | K40: - | L40: - | M40: - | N40: 3.5111001e+15 | O40: 46004 | P40: 446/15915/418.25/20220 | Q40: 46004
A41: 37 | B41: Cendy Santia KS, Amd AK | C41: Kediri | D41: 33851 | E41: D-III | G41: 3506154409920001 | H41: - | I41: - | J41: - | K41: - | L41: - | M41: - | N41: 16 14 5 2 1 19-3114432 | O41: 45539 | P41: 446/19670/418.25/2020 | Q41: 45539 | R41: Berkas STR belum ada
A42: 38 | B42: Mistiani Saputri, Amd Kom | C42: Kediri | D42: 35907 | E42: D-III | G42: 3506266204980003 | H42: - | I42: - | J42: - | K42: - | L42: - | M42: -
...

Sheet Sheet1
A1: Lampiran Akurasi Data Personal Pegawai
A3: NO | B3: NIP PEGAWAI | C3: NAMA | D3: ALAMAT | E3: EMAIL | F3: NO HP | G3: NO NPWP | H3: NIK | I3: NO KK | J3: NO BPJS | K3: NO KARPEG | L3: NO KARIS/KARSU | M3: STR | O3: SIP | Q3: KET
M4: NOMOR | N4: BERLAKU | O4: NOMOR | P4: BERLAKU
A5: 1 | B5: 19750423-200212-2-005 | C5: dr. Durotun Nafisa | D5: Dsn. Balongjeruk Rt/Rw 001/001 Ds. Balongjeruk Kec. Kunjang | E5: nafisa.fariddr@gmail.com | F5: 0812-5318-213 | G5: 24.933.183.6-655.000 | H5: 3506216304750001 | K5: 162303
A6: 2 | B6: 19810604-200902-2-004 | C6: drg. Putri Emyta L | D6: Jl. Medang Kamolan II/18 Rt/Rw 032/008 Ds. Balowerti Kec. Kota Kab. Kediri | E6: putriemyta04@gmail.com | F6: 0851-5747-8852 | G6: 34.359.132.7-531.000 | H6: 3506124406810001 | I6: 3571022812200010 | J6: 0000149032236 | K6: 313387
A7: 3 | B7: 19700508-199203-1-003 | C7: Setya Budi,S Kep, Ners | D7: Dsn. Pulorejo Rt/Rw 001/019 Ds. Krecek Kec. Badas | E7: setyab71@gmail.com | F7: 0812-4984-8689 | G7: 64.332.469.2-655.000 | H7: 3506260805700002 | I7: 3506261312101101 | J7: 0000112331092
A8: 4 | B8: 19671215-198811-2-002 | C8: Jema'i.,Amd.Keb | D8: Dsn. Blereng Rt/Rw 002/004 Ds. Sumberjo KeC. Purwoasri | E8: jemaimai67@gmail.com | F8: 0857-3269-9849 | G8: 64.317.176.2-655.000 | H8: 3506155512670001 | I8: 3506152604210002 | J8: 0000108061683 | K8: 734468
A9: 5 | B9: 19691030-199203-2-008 | C9: Luluk Listyaningsih.,Amd.Gz | D9: Dsn. Kunjang Kidul Rt/Rw 003/001 Ds. Kunjang Kec. Kunjang | E9: listyaningsihluluk@gmail.com | F9: 0852-3126-6158 | G9: 64.317.191.1-655.000 | H9: 3506217010690003 | I9: 3506211512100528 | J9: 0000108447546 | K9: 054048 | L9: 283980
A10: 6 | B10: 19810704-200901-1-004 | C10: Daril Rahmatullah.,S.Farm | D10: Jl. Supriyadi No.108 Rt/Rw 002/005 Desa Kudu Kec. Kertosono | E10: daril2day@gmail.com | F10: 0817-0419-935 | G10: 24.204.476.6-655.000 | H10: 3518080407810002
A11: 7 | B11: 19710125-199203-2-010 | C11: Yuanendah, SST | D11: Dsn. Maduh Rt/Rw 012/005 Ds. Pakis Kec. Kunjang | E11: yuanendah4@gmail.com | F11: 0822-5716-2779 | G11: 64.317.172.1-655.000 | H11: 3506216501710002 | I11: 3506212301200013 | J11: 0000108062177 | K11: 056043
A12: 8 | B12: 19810801-200604-2-027 | C12: Barokatul Fitriah S.Kep, Ners | D12: Dsn. Gampengrejo Rt/Rw 003/001 Ds. Ngampel Kec. Papar | E12: bfitriah94@gmail.com | F12: 0857-3642-2226 | G12: 66.794.113.2-655.000 | H12: 3506144108810002 | I12: 3506141208110002 | J12: 0000108061468 | K12: 205705
A13: 9 | B13: 19780908-199903-2-001 | C13: Fitri Ariani I Amd, AK | D13: Dsn. Muneng Wetan Rt/Rw 001/004 Ds. Muneng Kec. Purwoasri | E13: nabilazzamorin@gmail.com | F13: 0857-0689-7974 | G13: 70.947.843.2-602.000 | H13: 3517014809780002 | I13: 3506152808200003 | J13: 0000108061536 | K13: 102763
A14: 10 | B14: 19660909-198801-2-002 | C14: Umi Kulsum | D14: Dusun. Kapi Rt/Rw 008/002 Desa.Kapi Kec.Kunjang | E14: 09091966@gmail.com | F14: 0813-3596-7481 | G14: 64.317.174.7-655.000 | H14: 3506214909660002 | I14: 3506210912104148 | J14: 0000108061615 | K14: 820305
A15: 11 | B15: 19871127-201001-2-008 | C15: Rinda Ari Puspita.,Amd.KG | D15: Dsn. Kuripan Rt/Rw 001/002 Ds. Kendalsari Kec. Sumobito Kab. Jombang | E15: rindaari39@gmail.com | F15: 0821-4163-8954 | G15: 73.777.489.3-602.000 | H15: 3576026711870005 | I15: 3517111401150001 | J15: 0000200501987 | K15: 111454
A16: 12 | B16: 19960310-202203-1-005 | C16: dr.Rizky Rachmat Kurniawan | D16: Jl. Arumdalu no.146 Rt/Rw 002/002 Ds.Brenggolo Kec.Plosoklaten | E16: Richie.rachmat@gmail.com | F16: 0853-3121-8637 | G16: 91.775.407.9-724.000 | H16: 6408041003960005 | I16: 6408043110190015 | J16: 0000165972159
A17: 13 | B17: 19720306-200604-2-014 | C17: Supatemi, SST | D17: Dsn. Juwet Rt/Rw 006/002 Ds. Juwet Kec. Kunjang | E17: supatemivio@gmail.com | F17: 0812-1749-5433 | G17: 25.177.579.7-655.000 | H17: 3506214603720001 | I17: 3506212912110001 | J17: 0000108062087 | K17: 205742
A18: 14 | B18: 19740806-200604-2-022 | C18: Anik Sri Purwati.,Amd.Keb | D18: Dsn. Klepek Rt/Rw 006/002 Ds. Klepek Kec. Kunjang | E18: aniksripurwanti41@gmail.com | F18: 0822-3334-1030 | G18: 55.441.077.9-655.000 | H18: 3506214608740001 | I18: 3506210912100076 | J18: 0000108061424 | K18: 205758 | L18: 84333
A19: 15 | B19: 19741101-200604-2-014 | C19: Enny Nurhayati.,Amd.Keb | D19: Dsn. Kuwik Rt/Rw 002/002 Ds. Kuwik Kec. Kunjang | E19: enny.nurhayati1974@gmail.com | F19: 0856-0634-1768 | G19: 66.138.382.8-655.000 | H19: 3506214111740001 | I19: 3506211012102111 | J19: 0000108061514 | K19: 205710 | L19: 084372
A20: 16 | B20: 19750315-200604-2-031 | C20: Sulisni.,Amd.Keb | D20: Dsn. Gambiran Rt/Rw 001/002 Ds. Parelor Kec. Kunjang | E20: sulisniabhi@gmail.com | F20: 0812-3215-6810 | G20: 64.317.179.6-655.000 | H20: 3506215503750001 | I20: 3506211012103142 | J20: 0000108320894 | K20: 205743 | L20: 009841
A21: 17 | B21: 19751117-200701-2-010 | C21: Estu Rahayuningsih.,Amd.Keb | D21: Dsn. Bungkul Rt/Rw 004/007 Ds. Kapas Kec. Kunjang | E21: estuberlian@gmail.com | F21: 0822-5716-2779 | G21: 64.317.184.6-655.000 | H21: 3506215711750001 | I21: 3506210406120001 | J21: 0000108447243 | K21: 545918
A22: 18 | B22: 19760521-200701-2-012 | C22: Prihatiningtyas.,Amd.Keb | D22: Dsn. Tenggerlor Rt/Rw 001/001 Ds. Tenggerlor Kec.Kunjang | E22: prihatiningtyas35@gmail.com | F22: 0822-3063-6881 | G22: 55.617.482.9-655.000 | H22: 3506216105760001 | I22: 3506210712100412 | J22: 0000108447761 | K22: 545920
A23: 19 | B23: 19650614-199203-2-007 | C23: Istikaroh | D23: Dsn. Wonorejo Rt/Rw 003/001 Ds. Wonorejo Kec. Kunjang | E23: istikarohayu@gmail.com | F23: 0821-4238-8971 | G23: 64.317.182.0-655.000 | H23: 3506215406650002 | I23: 3506210912100603 | J23: 00001080616590 | K23: 989509
A24: 20 | B24: 19870803-201903-2-005 | C24: Siti Aminah. Amd. Kep | D24: Jl. Anjasmoro No. 5 Rt/Rw 002/005 Ds. Pare Kec. Pare | E24: daniswara.shety@gmail.com | F24: 0813-5717-2818 | G24: 83.362.987.6-655.000 | H24: 3506174308870002 | I24: 3506171907120022 | J24: 0001827151389 | L24: 02033841
A25: 21 | B25: 19970326-202012-2-013 | C25: Nuryana Vidya C, Amd.Kep | D25: Dsn. Kapi Rt/Rw 002/001 Ds. Kapi Kec.Kunjang | E25: nuryanav@gmail.com | F25: 0813-3314-3823 | G25: 96.961.365.2-655.000 | H25: 3506216603970003 | I25: 3506211011200001 | J25: 0002936133494
A26: 22 | B26: 19951125-202012-2-013 | C26: Novia Anjarwati, Amd. Kes | D26: Dsn. Juwono Rt/Rw 004/002 Ds. Juwono Kec. Kertosono | E26: noviaanjar25@gmail.com | F26: 0895-3684 -08637 | G26: 41.031.886.9-655.000 | H26: 3518086511950002 | I26: 3518080810200010 | J26: 0002908128666
A27: 23 | B27: 19790506-201001-1-027 | C27: Sito Luncono Setio Utomo | D27: Dsn. Menang Rt/Rw 002/004 Ds. Menang Kec. Pagu | E27: loencono79@gmail.com | F27: 0813-3551-0010 | G27: 70.062.870.4-952.000 | H27: 9111020605790003 | I27: 3506111012150001 | J27: 0001306953156 | K27: 067509 | L27: 02008812
A28: 24 | B28: 19930105-202221-2-001 | C28: Dinung Wahyu Purwanti | D28: Dsn. Gebyaran Rt/Rw 004/006 Ds. Puhjarak Kec. Plemahan | E28: dinungwahyu7@gmail.com | F28: 0857-9033-8197 | G28: 53.219.514.6-655.000 | H28: 3506164501930001 | I28: 3506160610170002 | J28: 0003281394993
A29: 25 | B29: 19870507-201402-2-001 | C29: Mey Idayati, A.Md.Kep | D29: Dsn. Sugih Waras Rt/Rw 002/002 Ds.Kuwik Kec.Kunjang | E29: meiidayati34@gmail.com | F29: 0856-4995-5671 | G29: 66.815.556.7-655.000 | H29: 3506214705870000 | I29: 3506211711160000 | J29: 0000675751623 | K29: B 02002464 | L29: BB 02001834 | M29: 16 01 5 2 2 21-4011045 | N29: 46149 | O29: 503.2/586.1/kab/sipp/vll/2021 | P29: 46149
C32: Keterangan : | H32: Kepala UPTD Puskesmas Kunjang
B33: 1 | C33: Format File dalam bentuk excel
B34: 2 | C34: Penulisan NIP diberi tanda strip "-" (Sesuai Contoh)
H36: dr. Durotun Nafisa
H37: NIP. 19750423 200212 2 005

Sheet Sheet2
A1: No | B1: Nama | C1: STR | D1: BERLAKU | E1: SIP | F1: BERLAKU | G1: KET
A2: 1 | B2: BU AFIS | G2: STR MATI
A3: 2 | B3: ENDAH | G3: sip tidak ada
A4: 3 | B4: bu fitri | G4: mati semua
A5: 4 | B5: bu rinda | G5: sip mati
A6: 5 | B6: dr rizky | G6: sip tidak ada
A7: 6 | B7: bu supatemi | G7: sip tidak ada
A8: 7 | B8: bu tyas | G8: tidak ada semua
A9: 8 | B9: novi | G9: sip tidak ada
A10: 9 | B10: della | G10: sip tidak ada
A11: 10 | B11: indri | G11: tidak ada semua
A12: 11 | B12: cendy | G12: tidak ada semua
A13: 12 | B13: dr edwin | G13: sip tidak ada

Sheet Sheet3
A2: NO | B2: NAMA | C2: NIK
A3: 1 | B3: dr. Durotun Nafisa | C3: 3506216304750001
A4: 2 | B4: drg. Putri Emyta L | C4: 3506124406810001
A5: 3 | B5: Setya Budi,S Kep, Ners | C5: 3506260805700002
A6: 4 | B6: Jema'i.,Amd.Keb | C6: 3506155512670001
A7: 5 | B7: Luluk Listyaningsih.,Amd.Gz | C7: 3506217010690003
A8: 6 | B8: Daril Rahmatullah.,S.Farm | C8: 3518080407810002
A9: 7 | B9: Yuanendah, SST | C9: 3506216501710002
A10: 8 | B10: Barokatul Fitriah S.Kep, Ners | C10: 3506144108810002
A11: 9 | B11: Fitri Ariani I Amd, AK | C11: 3517014809780002
A12: 10 | B12: Umi Kulsum | C12: 3506214909660002
A13: 11 | B13: Rinda Ari Puspita.,Amd.KG | C13: 3576026711870005
A14: 12 | B14: dr.Rizky Rachmat Kurniawan | C14: 6408041003960005
... A43: 41 | B43: Shalikul Hadi, SKM | C43: 3506161109000001

Sheet Sheet4
A1: DAFTAR STR DAN SIP PEGAWAI
A2: UPTD PUSKESMAS KUNJANG
A4: No | B4: Nama | C4: STR | E4: SIP | G4: Ket
C5: Nomer | D5: Berlaku | E5: Nomer | F5: Berlaku
A6: 1 | B6: dr.Durotun Nafisa | C6: 35 2 1 100 4 22 012392 | D6: 46500 | E6: 446/3247/418.25/2022 | F6: 46500 | G6: Berkas STR belum ada
A7: 2 | B7: drg. Putri Emyta Sari | C7: 3522100422022576 | D7: 46542 | E7: 446/5418/418.25/2022 | F7: 46542
A8: 3 | B8: Jema’I, Amd.. Keb. | C8: 16 02 5 2 2 22-4473580 | D8: 46736 | E8: 446/17418/418.25/2022 | F8: 46736
A9: 4 | B9: Setya Budi, Amd., Kep | C9: 16 01 7 2 2 22-4376440 | D9: 46515 | E9: 446/13309/418.25/2022 | F9: 46515
A10: 5 | B10: Luluk Listyaningsih,AMG | C10: 16 09 5 2 21 23/4750531 | D10: 47056 | E10: 446/16.410/418.25/2028 | F10: 47056
A11: 6 | B11: Yuanendah, SST. | C11: 16 02 6 2 2 22-4545675 | D11: 46412 | G11: SIP belum ada
A12: 7 | B12: Daril Rahmatullah, S. Farm. | C12: 19810704/STRA-UGM/2005/12051 | D12: 46207 | E12: 19810704/SIPA-35.06/2021/1162 | F12: 46207
A13: 8 | B13: Fitri Ariani Isnaningtyas, Amd.AK | C13: 16 14 5 2 2 17-2135509 | D13: 44812 | E13: 446/19671/418.25/2020 | F13: 44812 | G13: STR dan SIP Mati
A14: 10 | B14: Rinda Ari Puspita, Amd. KG | C14: 16 04 5 2 2 22-4497124 | D14: 46718 | E14: 446/18760/418.25/2022 | F14: 46718
A15: 11 | B15: dr. Rizky Rachmat Kurniawan | C15: 3511100120219553 | D15: 45361 | E15: 446/4821/418.25/2022 | F15: 45361
A16: 12 | B16: Supatemi, Amd.Keb | C16: 16 02 6 2 2 23-4572343 | D16: 46818 | E16: 446/2431/418.25/2020 | F16: 44626 | G16: SIP Mati
A17: 13 | B17: Anik Sri Purwati, Amd. Keb. | C17: 16 02 5 2 2 22-4468115 | D17: 46605 | E17: 446/17079/418.25/2022 | F17: 06/082027
A18: 14 | B18: Enny Nurhayati, Amd.. Keb. | C18: 16 02 5 2 2 22-4533496 | D18: 46692 | E18: 446/1315/418.25/2023 | F18: 46692
A19: 15 | B19: Sulisni, Amd. Keb. | C19: 16 02 5 2 2 22-4258495 | D19: 46461 | E19: 446/6909/418.25/2022 | F19: 46461
A20: 16 | B20: Estu Rahayuningsih, Amd. Keb. | C20: 16 02 5 2 2 22-4503131 | D20: 46708 | E20: 446/183/418.25/2023 | F20: 46708
A21: 17 | B21: Prihatiningtyas, Amd. Keb. | C21: 16 02 5 2 1 17-2096355 | D21: 44702 | E21: 446/21.304/418.25/2018 | F21: 44702 | G21: STR dan SIP Mati
A22: 18 | B22: Mey Idayati, Amd.Kep | C22: 16 01 5 2 2 21-4011045 | D22: 46149 | E22: KS.06/1813/418.25/2023 | F22: 46149
A23: 20 | B23: Sito Luncono Setio Utomo
A24: 21 | B24: Siti Aminah, Amd Kep. | C24: 16 01 5 2 2 19-3076593 | D24: 45507 | E24: 446/1334/418.25/2020 | F24: 45507 | K24: `
A25: 22 | B25: Nuryana Vidya C, Amd.Kep | C25: YV00001133815193 | D25: 45377 | E25: 446/20242/418.25/2022 | F25: 45377
A26: 23 | B26: Novia Anjarwati, Amd. Kes | C26: 16 12 5 2 1 18-1578599 | D26: 45255 | E26: KS.06/198/418.25/9/2023 | F26: 45255
A27: 24 | B27: Dinung Wahyu Purwanti | C27: 16 02 5 2 1 19-3055219 | D27: 45296 | E27: 446/1616/418.25/2022 | F27: 45296
A28: 25 | B28: Susi Winda Wandari, Amd Keb | C28: 16 02 5 2 2 23-4784611 | D28: 46848 | E28: KS.06/707/418.25/9/2023 | F28: 46848
A29: 26 | B29: Desi Natalia, SST | C29: 16 02 5 2 2 23-4622522 | D29: 47111 | E29: KS.06/1440/418.25/2023 | F29: 47111
A30: 27 | B30: Devi Ardianti, SE
A31: 28 | B31: Vivi Juni Mega A, S.Tr.Keb | C31: 16 02 5 2 1 19-3161528 | D31: 45448 | E31: 446/1344/418.25/2020 | F31: 45448
A32: 29 | B32: Anieta Yuni Purnawati, Amd.Keb | C32: 16 02 5 2 1 19-2426282 | D32: 45460 | E32: 446/19.141/418.25/2019 | F32: 45460
A33: 30 | B33: Della Karisma Lutfiana, Amd. Gz | C33: 16 09 5 2 2 23-4752009 | D33: 46849 | E33: 446/18.069/418.25/2019 | F33: 45022 | G33: SIP Mati
A34: 31 | B34: Slamet Riadi
A35: 32 | B35: Anita Sumariati
A36: 33 | B36: Mimin Asmawati
A37: 34 | B37: Shindy Erlina Putri Pramujib
A38: 35 | B38: Fitria Indriyani | G38: STR dan SIP belum ada
A39: 37 | B39: Cendy Santia KS, Amd AK | C39: 16 14 5 2 1 19-3114432 | D39: 45539 | E39: 446/19670/418.25/2020 | F39: 45539
A40: 38 | B40: Mistiani Saputri, Amd Kom
A41: 39 | B41: Rani Rosita , Amd Keb | C41: 16 02 5 2 1 18-2200918 | D41: 45244 | E41: 446/4569/418.25/2022 | F41: 45244
...

Sheet Sheet5
A1: REKAP KINERJA PEGAWAI
A2: UPTD PUSKESMAS KUNJANG
A3: Tahun 2023
A5: No | B5: Nama | C5: Januari | E5: Februari | G5: Maret | I5: April | K5: Mei | M5: Juni | O5: Juli | Q5: Agustus | S5: September | U5: Oktober | W5: November | Y5: Desember
C6: Kinerja | D6: Prosentase | E6: Kinerja | F6: Prosentase | G6: Kinerja | H6: Prosentase | I6: Kinerja | J6: Prosentase | K6: Kinerja | L6: Prosentase | M6: Kinerja | N6: Prosentase | O6: Kinerja | P6: Prosentase | Q6: Kinerja | R6: Prosentase | S6: Kinerja | T6: Prosentase | U6: Kinerja | V6: Prosentase | W6: Kinerja | X6: Prosentase | Y6: Kinerja | Z6: Prosentase
C7: ( Menit ) | D7: ( % ) | E7: ( Menit ) | F7: ( % ) | G7: ( Menit ) | H7: ( % ) | I7: ( Menit ) | J7: ( % ) | K7: ( Menit ) | L7: ( % ) | M7: ( Menit ) | N7: ( % ) | O7: ( Menit ) | P7: ( % ) | Q7: ( Menit ) | R7: ( % ) | S7: ( Menit ) | T7: ( % ) | U7: ( Menit ) | V7: ( % ) | W7: ( Menit ) | X7: ( % ) | Y7: ( Menit ) | Z7: ( % )
A8: 1 | B8: dr.Durotun Nafisa
A9: 2 | B9: drg. Putri Emyta Sari | C9: 8620 | D9: 127.70% | E9: 7665 | F9: 113.56% | G9: 8850 | H9: 131.11% | I9: 5120 | J9: 75.85% | K9: 6790 | L9: 100.59% | M9: 7070 | N9: 104.74 | O9: 6450 | P9: 95.56% | Q9: 7450 | R9: 110.37%
A10: 3 | B10: Jema’I, Amd.. Keb. | C10: 8130 | D10: 120.44% | E10: 5430 | F10: 80.44% | G10: 8070 | H10: 119.56% | I10: 5580 | J10: 82.67% | K10: 6660 | L10: 98.67% | M10: 4800 | N10: 71.11% | O10: 7470 | P10: 110.67% | Q10: 8280 | R10: 122.67% | S10: 8220 | T10: 121.78% | U10: 7590 | V10: 1.1244
A11: 4 | B11: Setya Budi, Amd., Kep | C11: 5195 | D11: 76.96% | E11: 6670 | F11: 98.81% | G11: 7020 | H11: 1.04 | I11: 4230 | J11: 62.67% | K11: 7490 | L11: 110.96% | M11: 4530 | N11: 67.11% | O11: 6240 | P11: 92.44% | Q11: 9050 | R11: 134.07%
A12: 5 | B12: Luluk Listyaningsih,AMG | C12: 9410 | D12: 139.41% | E12: 2790 | F12: 41.33% | G12: 8640 | H12: 1.28 | I12: 5600 | J12: 82.96% | K12: 8943 | L12: 132.49% | M12: 6975 | N12: 103.33% | O12: 8985 | P12: 133.11% | Q12: 9270 | R12: 137.33% | S12: 9140 | T12: 1.3541 | U12: 8925 | V12: 1.3222 | W12: 9120 | X12: 1.3511 | Y12: 7740 | Z12: 1.1467
A13: 6 | B13: Yuanendah, SST.
A14: 7 | B14: Daril Rahmatullah, S. Farm. | D14: 99.78% | F14: 58.37% | H14: 117.33% | J14: 42.22% | L14: 79.11% | N14: 81.78% | P14: 84.44% | R14: 127.93% | S14: 7665 | T14: 113.56%
A15: 8 | B15: Fitri Ariani Isnaningtyas, Amd.AK | C15: 4255 | D15: 63.04% | E15: 3861 | F15: 57.20% | G15: 2975 | H15: 44.07% | I15: 1260 | J15: 18.67% | K15: 4855 | L15: 71.93% | M15: 1570 | N15: 23.26% | O15: 6445 | P15: 95.48 | Q15: 8275 | R15: 122.59%
A16: 9 | B16: Umi Kulsum
A17: 10 | B17: Rinda Ari Puspita, Amd. KG | C17: 7635 | D17: 113.11% | E17: 7440 | F17: 116.22% | G17: 6900 | H17: 102.22% | I17: 5970 | J17: 88.44% | K17: 8160 | L17: 120.89% | M17: 5460 | N17: 80.89% | O17: 8040 | P17: 119.11% | Q17: 8480 | R17: 125.63% | S17: 8960 | T17: 132.74%
A18: 11 | B18: dr. Rizky Rachmat Kurniawan
A19: 12 | B19: Supatemi, Amd.Keb | C19: 9151 | D19: 1.3563 | E19: 8550 | F19: 1.2667 | G19: 7655 | H19: 1.1341 | I19: 5489 | J19: 0.8132 | K19: 8520 | L19: 1.2622 | M19: 6925 | N19: 1.0259 | O19: 9055 | P19: 1.3415 | Q19: 9225 | R19: 136.67% | S19: 9225 | T19: 136.67% | U19: 8520 | V19: 1.2622 | W19: 9109 | X19: 1.3495 | Y19: 7090 | Z19: 1.0504
A20: 13 | B20: Anik Sri Purwati, Amd. Keb. | C20: 7285 | D20: 107.93% | E20: 7080 | F20: 104.89% | G20: 7080 | H20: 104.89% | I20: 5485 | J20: 81.26% | K20: 8115 | L20: 120.22% | M20: 6632 | N20: 98.25% | O20: 6775 | P20: 100.37% | Q20: 8750 | R20: 129.63% | S20: 7345 | T20: 108.81% | U20: 8195 | V20: 1.2141 | W20: 7585 | X20: 1.1237 | Y20: 6385 | Z20: 0.9459
A21: 14 | B21: Enny Nurhayati, Amd.. Keb. | C21: 8295 | D21: 122.89% | E21: 7660 | F21: 113.48% | G21: 7350 | H21: 108.89% | I21: 6555 | J21: 97.11% | K21: 8220 | L21: 121.78% | M21: 7515 | N21: 111.33% | O21: 8505 | P21: 1.26 | Q21: 8955 | R21: 132.67% | S21: 8430 | T21: 124.89% | U21: 9570 | V21: 1.4178 | W21: 9420 | X21: 1.3956 | Y21: 7905 | Z21: 1.1711
A22: 15 | B22: Sulisni, Amd. Keb. | C22: 8700 | D22: 128.89% | E22: 8580 | F22: 127.11% | G22: 8396 | H22: 124.39% | I22: 6745 | J22: 99.93% | K22: 8985 | L22: 133.11% | M22: 7855 | N22: 116.37% | O22: 8480 | P22: 125.63% | Q22: 9825 | R22: 145.56% | S22: 9075 | T22: 134.44% | U22: 9345 | V22: 1.3844 | W22: 8510 | X22: 126.07% | Y22: 8170 | Z22: 1.2104
A23: 16 | B23: Estu Rahayuningsih, Amd. Keb. | C23: 8990 | D23: 133.19% | E23: 7650 | F23: 113.33% | G23: 8190 | H23: 121.33% | I23: 8190 | J23: 121.33% | K23: 8190 | L23: 121.33% | M23: 8190 | N23: 121.33% | O23: 8280 | P23: 1.2267 | Q23: 9510 | R23: 1.4089 | S23: 8950 | T23: 132.59% | U23: 8760 | V23: 1.2978 | W23: 8460 | X23: 1.2533 | Y23: 5460 | Z23: 0.8089
A24: 17 | B24: Prihatiningtyas, Amd. Keb. | C24: 6645 | D24: 98.44% | E24: 6647 | F24: 98.47% | G24: 7174 | I24: 5415 | J24: 80.22% | K24: 8074 | L24: 119.61% | M24: 6600 | N24: 97.78% | O24: 5680 | P24: 84.15% | Q24: 8010 | R24: 118.67%
A25: 18 | B25: Mey Idayati, Amd.Kep | C25: 7070 | D25: 104.74% | E25: 8200 | F25: 121.48% | G25: 7995 | H25: 118.44% | I25: 6454 | K25: 8425 | L25: 124.81% | M25: 7425 | N25: 110.00% | O25: 8960 | P25: 132.74% | Q25: 8110 | R25: 120.15%
A26: 19 | B26: Sito Luncono Setio Utomo | C26: 7035 | D26: 104.22 | E26: 7015 | F26: 103.93 | G26: 8335 | H26: 123.48 | I26: 8335 | J26: 123.48 | K26: 8355 | L26: 123.48 | M26: 7175 | N26: 106.3 | O26: 7175 | P26: 106.3 | Q26: 7755 | R26: 114.89 | S26: 8570 | T26: 126.96% | U26: 9200 | V26: 1.363 | W26: 8440 | X26: 1.2504 | Y26: 6050 | Z26: 0.8963
A27: 20 | B27: Siti Aminah, Amd Kep. | C27: 9340 | D27: 138.37% | E27: 8490 | F27: 125.78% | G27: 9270 | H27: 137.33% | I27: 6810 | J27: 100.89% | K27: 9390 | L27: 139.11% | M27: 7830 | N27: 1.16 | O27: 8250 | P27: 122.22% | Q27: 9765 | R27: 144.67% | S27: 9080 | T27: 134.52% | U27: 9620 | V27: 1.4252
A28: 21 | B28: Nuryana Vidya C, Amd.Kep | C28: 6350 | E28: 7930 | F28: 117.48% | G28: 9000 | H28: 133.33% | I28: 5460 | J28: 80.89% | K28: 8000 | L28: 118.52% | M28: 7720 | N28: 114.37% | O28: 8320 | P28: 123.26% | Q28: 8970 | R28: 132.89% | S28: 8210 | T28: 121.63%
A29: 22 | B29: Novia Anjarwati, Amd. Kes | C29: 8750 | D29: 129.63% | E29: 8435 | F29: 124.96% | G29: 8675 | H29: 128.52% | I29: 5810 | J29: 86.07% | K29: 9370 | L29: 138.81% | M29: 7810 | N29: 115.70% | O29: 8800 | P29: 130.37% | Q29: 9460 | R29: 140.15% | S29: 8210 | T29: 1.2163 | U29: 6190 | V29: 0.917 | W29: 7750 | X29: 1.1481 | Y29: 6650 | Z29: 0.9852
A30: 23 | B30: Dinung Wahyu Purwanti | C30: 6805 | D30: 100.81% | E30: 6757 | F30: 100.10% | G30: 7255 | H30: 107.48% | I30: 2435 | J30: 36.07% | O30: 3980 | P30: 58.96% | Q30: 7610 | R30: 112.74%
A31: 24 | B31: Susi Winda Wandari, Amd Keb | K31: 6160 | L31: 91.26% | M31: 6215 | N31: 92.07% | O31: 8280 | P31: 122.67% | Q31: 9270 | R31: 137.33% | S31: 7940 | T31: 117.63%

Sheet Sheet6
A1: ABSENSI KEGIATAN OUT BOND
A2: UPTD PUSKESMAS KUNJANG
A3: TGL 20 JANUARI 2024
A5: No | B5: Nama | C5: Keluarga | D5: Ket | E5: KET
A7: 1 | B7: dr.Durotun Nafisa | C7: 3
A8: 2 | B8: drg. Putri Emyta Sari | C8: 1
A9: 3 | B9: Jema’I, Amd.. Keb. | C9: 3
A10: 4 | B10: Setya Budi, Amd., Kep | C10: 0
A11: 5 | B11: Luluk Listyaningsih,AMG | C11: 1
A12: 6 | B12: Yuanendah, SST. | C12: 2 | D12: 1 balita
